MotChallenge2DBox

multiprocessing.pool.RemoteTraceback: 
"""
Traceback (most recent call last):
  File "/data1/yfzhang/anaconda3/lib/python3.11/multiprocessing/pool.py", line 125, in worker
    result = (True, func(*args, **kwds))
                    ^^^^^^^^^^^^^^^^^^^
  File "/data1/yfzhang/anaconda3/lib/python3.11/multiprocessing/pool.py", line 48, in mapstar
    return list(map(*args))
           ^^^^^^^^^^^^^^^^
  File "/home/yfzhang/DanceTrack/TrackEval/trackeval/_timing.py", line 64, in wrap
    return f(*args, **kw)
           ^^^^^^^^^^^^^^
  File "/home/yfzhang/DanceTrack/TrackEval/trackeval/eval.py", line 191, in eval_sequence
    raw_data = dataset.get_raw_seq_data(tracker, seq)
               ^^^^^^^^^^^^^^^^^^^^^^^^^^^^^^^^^^^^^^
  File "/home/yfzhang/DanceTrack/TrackEval/trackeval/_timing.py", line 64, in wrap
    return f(*args, **kw)
           ^^^^^^^^^^^^^^
  File "/home/yfzhang/DanceTrack/TrackEval/trackeval/datasets/_base_dataset.py", line 92, in get_raw_seq_data
    raw_gt_data = self._load_raw_file(tracker, seq, is_gt=True)
                  ^^^^^^^^^^^^^^^^^^^^^^^^^^^^^^^^^^^^^^^^^^^^^
  File "/home/yfzhang/DanceTrack/TrackEval/trackeval/datasets/mot_challenge_2d_box.py", line 227, in _load_raw_file
    time_data = np.asarray(read_data[time_key], dtype=np.float)
                                                      ^^^^^^^^
  File "/data1/yfzhang/anaconda3/lib/python3.11/site-packages/numpy/__init__.py", line 305, in __getattr__
    raise AttributeError(__former_attrs__[attr])
AttributeError: module 'numpy' has no attribute 'float'.
`np.float` was a deprecated alias for the builtin `float`. To avoid this error in existing code, use `float` by itself. Doing this will not modify any behavior and is safe. If you specifically wanted the numpy scalar type, use `np.float64` here.
The aliases was originally deprecated in NumPy 1.20; for more details and guidance see the original release note at:
    https://numpy.org/devdocs/release/1.20.0-notes.html#deprecations
"""

The above exception was the direct cause of the following exception:

Traceback (most recent call last):
  File "/home/yfzhang/DanceTrack/TrackEval/trackeval/eval.py", line 81, in evaluate
    results = pool.map(_eval_sequence, seq_list)
              ^^^^^^^^^^^^^^^^^^^^^^^^^^^^^^^^^^
  File "/data1/yfzhang/anaconda3/lib/python3.11/multiprocessing/pool.py", line 367, in map
    return self._map_async(func, iterable, mapstar, chunksize).get()
           ^^^^^^^^^^^^^^^^^^^^^^^^^^^^^^^^^^^^^^^^^^^^^^^^^^^^^^^^^
  File "/data1/yfzhang/anaconda3/lib/python3.11/multiprocessing/pool.py", line 774, in get
    raise self._value
AttributeError: module 'numpy' has no attribute 'float'.
`np.float` was a deprecated alias for the builtin `float`. To avoid this error in existing code, use `float` by itself. Doing this will not modify any behavior and is safe. If you specifically wanted the numpy scalar type, use `np.float64` here.
The aliases was originally deprecated in NumPy 1.20; for more details and guidance see the original release note at:
    https://numpy.org/devdocs/release/1.20.0-notes.html#deprecations





MotChallenge2DBox

multiprocessing.pool.RemoteTraceback: 
"""
Traceback (most recent call last):
  File "/data1/yfzhang/anaconda3/lib/python3.11/multiprocessing/pool.py", line 125, in worker
    result = (True, func(*args, **kwds))
                    ^^^^^^^^^^^^^^^^^^^
  File "/data1/yfzhang/anaconda3/lib/python3.11/multiprocessing/pool.py", line 48, in mapstar
    return list(map(*args))
           ^^^^^^^^^^^^^^^^
  File "/home/yfzhang/DanceTrack/TrackEval/trackeval/_timing.py", line 64, in wrap
    return f(*args, **kw)
           ^^^^^^^^^^^^^^
  File "/home/yfzhang/DanceTrack/TrackEval/trackeval/eval.py", line 191, in eval_sequence
    raw_data = dataset.get_raw_seq_data(tracker, seq)
               ^^^^^^^^^^^^^^^^^^^^^^^^^^^^^^^^^^^^^^
  File "/home/yfzhang/DanceTrack/TrackEval/trackeval/_timing.py", line 64, in wrap
    return f(*args, **kw)
           ^^^^^^^^^^^^^^
  File "/home/yfzhang/DanceTrack/TrackEval/trackeval/datasets/_base_dataset.py", line 92, in get_raw_seq_data
    raw_gt_data = self._load_raw_file(tracker, seq, is_gt=True)
                  ^^^^^^^^^^^^^^^^^^^^^^^^^^^^^^^^^^^^^^^^^^^^^
  File "/home/yfzhang/DanceTrack/TrackEval/trackeval/datasets/mot_challenge_2d_box.py", line 227, in _load_raw_file
    time_data = np.asarray(read_data[time_key], dtype=np.float)
                                                      ^^^^^^^^
  File "/data1/yfzhang/anaconda3/lib/python3.11/site-packages/numpy/__init__.py", line 305, in __getattr__
    raise AttributeError(__former_attrs__[attr])
AttributeError: module 'numpy' has no attribute 'float'.
`np.float` was a deprecated alias for the builtin `float`. To avoid this error in existing code, use `float` by itself. Doing this will not modify any behavior and is safe. If you specifically wanted the numpy scalar type, use `np.float64` here.
The aliases was originally deprecated in NumPy 1.20; for more details and guidance see the original release note at:
    https://numpy.org/devdocs/release/1.20.0-notes.html#deprecations
"""

The above exception was the direct cause of the following exception:

Traceback (most recent call last):
  File "/home/yfzhang/DanceTrack/TrackEval/trackeval/eval.py", line 81, in evaluate
    results = pool.map(_eval_sequence, seq_list)
              ^^^^^^^^^^^^^^^^^^^^^^^^^^^^^^^^^^
  File "/data1/yfzhang/anaconda3/lib/python3.11/multiprocessing/pool.py", line 367, in map
    return self._map_async(func, iterable, mapstar, chunksize).get()
           ^^^^^^^^^^^^^^^^^^^^^^^^^^^^^^^^^^^^^^^^^^^^^^^^^^^^^^^^^
  File "/data1/yfzhang/anaconda3/lib/python3.11/multiprocessing/pool.py", line 774, in get
    raise self._value
AttributeError: module 'numpy' has no attribute 'float'.
`np.float` was a deprecated alias for the builtin `float`. To avoid this error in existing code, use `float` by itself. Doing this will not modify any behavior and is safe. If you specifically wanted the numpy scalar type, use `np.float64` here.
The aliases was originally deprecated in NumPy 1.20; for more details and guidance see the original release note at:
    https://numpy.org/devdocs/release/1.20.0-notes.html#deprecations





MotChallenge2DBox

multiprocessing.pool.RemoteTraceback: 
"""
Traceback (most recent call last):
  File "/data1/yfzhang/anaconda3/lib/python3.11/multiprocessing/pool.py", line 125, in worker
    result = (True, func(*args, **kwds))
                    ^^^^^^^^^^^^^^^^^^^
  File "/data1/yfzhang/anaconda3/lib/python3.11/multiprocessing/pool.py", line 48, in mapstar
    return list(map(*args))
           ^^^^^^^^^^^^^^^^
  File "/home/yfzhang/DanceTrack/TrackEval/trackeval/_timing.py", line 64, in wrap
    return f(*args, **kw)
           ^^^^^^^^^^^^^^
  File "/home/yfzhang/DanceTrack/TrackEval/trackeval/eval.py", line 191, in eval_sequence
    raw_data = dataset.get_raw_seq_data(tracker, seq)
               ^^^^^^^^^^^^^^^^^^^^^^^^^^^^^^^^^^^^^^
  File "/home/yfzhang/DanceTrack/TrackEval/trackeval/_timing.py", line 64, in wrap
    return f(*args, **kw)
           ^^^^^^^^^^^^^^
  File "/home/yfzhang/DanceTrack/TrackEval/trackeval/datasets/_base_dataset.py", line 92, in get_raw_seq_data
    raw_gt_data = self._load_raw_file(tracker, seq, is_gt=True)
                  ^^^^^^^^^^^^^^^^^^^^^^^^^^^^^^^^^^^^^^^^^^^^^
  File "/home/yfzhang/DanceTrack/TrackEval/trackeval/datasets/mot_challenge_2d_box.py", line 227, in _load_raw_file
    time_data = np.asarray(read_data[time_key], dtype=np.float)
                                                      ^^^^^^^^
  File "/data1/yfzhang/anaconda3/lib/python3.11/site-packages/numpy/__init__.py", line 305, in __getattr__
    raise AttributeError(__former_attrs__[attr])
AttributeError: module 'numpy' has no attribute 'float'.
`np.float` was a deprecated alias for the builtin `float`. To avoid this error in existing code, use `float` by itself. Doing this will not modify any behavior and is safe. If you specifically wanted the numpy scalar type, use `np.float64` here.
The aliases was originally deprecated in NumPy 1.20; for more details and guidance see the original release note at:
    https://numpy.org/devdocs/release/1.20.0-notes.html#deprecations
"""

The above exception was the direct cause of the following exception:

Traceback (most recent call last):
  File "/home/yfzhang/DanceTrack/TrackEval/trackeval/eval.py", line 81, in evaluate
    results = pool.map(_eval_sequence, seq_list)
              ^^^^^^^^^^^^^^^^^^^^^^^^^^^^^^^^^^
  File "/data1/yfzhang/anaconda3/lib/python3.11/multiprocessing/pool.py", line 367, in map
    return self._map_async(func, iterable, mapstar, chunksize).get()
           ^^^^^^^^^^^^^^^^^^^^^^^^^^^^^^^^^^^^^^^^^^^^^^^^^^^^^^^^^
  File "/data1/yfzhang/anaconda3/lib/python3.11/multiprocessing/pool.py", line 774, in get
    raise self._value
AttributeError: module 'numpy' has no attribute 'float'.
`np.float` was a deprecated alias for the builtin `float`. To avoid this error in existing code, use `float` by itself. Doing this will not modify any behavior and is safe. If you specifically wanted the numpy scalar type, use `np.float64` here.
The aliases was originally deprecated in NumPy 1.20; for more details and guidance see the original release note at:
    https://numpy.org/devdocs/release/1.20.0-notes.html#deprecations





MotChallenge2DBox
''
multiprocessing.pool.RemoteTraceback: 
"""
Traceback (most recent call last):
  File "/home/yfzhang/DanceTrack/TrackEval/trackeval/datasets/_base_dataset.py", line 152, in _load_simple_text_file
    fp = open(file)
FileNotFoundError: [Errno 2] No such file or directory: "val/my1frame/''/''/dancetrack0004.txt"

During handling of the above exception, another exception occurred:

Traceback (most recent call last):
  File "/data1/yfzhang/anaconda3/envs/dancetrack/lib/python3.7/multiprocessing/pool.py", line 121, in worker
    result = (True, func(*args, **kwds))
  File "/data1/yfzhang/anaconda3/envs/dancetrack/lib/python3.7/multiprocessing/pool.py", line 44, in mapstar
    return list(map(*args))
  File "/home/yfzhang/DanceTrack/TrackEval/trackeval/_timing.py", line 64, in wrap
    return f(*args, **kw)
  File "/home/yfzhang/DanceTrack/TrackEval/trackeval/eval.py", line 191, in eval_sequence
    raw_data = dataset.get_raw_seq_data(tracker, seq)
  File "/home/yfzhang/DanceTrack/TrackEval/trackeval/_timing.py", line 64, in wrap
    return f(*args, **kw)
  File "/home/yfzhang/DanceTrack/TrackEval/trackeval/datasets/_base_dataset.py", line 93, in get_raw_seq_data
    raw_tracker_data = self._load_raw_file(tracker, seq, is_gt=False)
  File "/home/yfzhang/DanceTrack/TrackEval/trackeval/datasets/mot_challenge_2d_box.py", line 201, in _load_raw_file
    read_data, ignore_data = self._load_simple_text_file(file, is_zipped=self.data_is_zipped, zip_file=zip_file)
  File "/home/yfzhang/DanceTrack/TrackEval/trackeval/datasets/_base_dataset.py", line 211, in _load_simple_text_file
    file))
trackeval.utils.TrackEvalException: File dancetrack0004.txt cannot be read because it is either not present or invalidly formatted
"""

The above exception was the direct cause of the following exception:

Traceback (most recent call last):
  File "/home/yfzhang/DanceTrack/TrackEval/trackeval/eval.py", line 81, in evaluate
    results = pool.map(_eval_sequence, seq_list)
  File "/data1/yfzhang/anaconda3/envs/dancetrack/lib/python3.7/multiprocessing/pool.py", line 268, in map
    return self._map_async(func, iterable, mapstar, chunksize).get()
  File "/data1/yfzhang/anaconda3/envs/dancetrack/lib/python3.7/multiprocessing/pool.py", line 657, in get
    raise self._value
trackeval.utils.TrackEvalException: File dancetrack0004.txt cannot be read because it is either not present or invalidly formatted





MotChallenge2DBox

multiprocessing.pool.RemoteTraceback: 
"""
Traceback (most recent call last):
  File "/data1/yfzhang/anaconda3/lib/python3.11/multiprocessing/pool.py", line 125, in worker
    result = (True, func(*args, **kwds))
                    ^^^^^^^^^^^^^^^^^^^
  File "/data1/yfzhang/anaconda3/lib/python3.11/multiprocessing/pool.py", line 48, in mapstar
    return list(map(*args))
           ^^^^^^^^^^^^^^^^
  File "/home/yfzhang/DanceTrack/TrackEval/trackeval/_timing.py", line 64, in wrap
    return f(*args, **kw)
           ^^^^^^^^^^^^^^
  File "/home/yfzhang/DanceTrack/TrackEval/trackeval/eval.py", line 191, in eval_sequence
    raw_data = dataset.get_raw_seq_data(tracker, seq)
               ^^^^^^^^^^^^^^^^^^^^^^^^^^^^^^^^^^^^^^
  File "/home/yfzhang/DanceTrack/TrackEval/trackeval/_timing.py", line 64, in wrap
    return f(*args, **kw)
           ^^^^^^^^^^^^^^
  File "/home/yfzhang/DanceTrack/TrackEval/trackeval/datasets/_base_dataset.py", line 92, in get_raw_seq_data
    raw_gt_data = self._load_raw_file(tracker, seq, is_gt=True)
                  ^^^^^^^^^^^^^^^^^^^^^^^^^^^^^^^^^^^^^^^^^^^^^
  File "/home/yfzhang/DanceTrack/TrackEval/trackeval/datasets/mot_challenge_2d_box.py", line 228, in _load_raw_file
    time_data = np.asarray(read_data[time_key], dtype=np.float)
                                                      ^^^^^^^^
  File "/data1/yfzhang/anaconda3/lib/python3.11/site-packages/numpy/__init__.py", line 305, in __getattr__
    raise AttributeError(__former_attrs__[attr])
AttributeError: module 'numpy' has no attribute 'float'.
`np.float` was a deprecated alias for the builtin `float`. To avoid this error in existing code, use `float` by itself. Doing this will not modify any behavior and is safe. If you specifically wanted the numpy scalar type, use `np.float64` here.
The aliases was originally deprecated in NumPy 1.20; for more details and guidance see the original release note at:
    https://numpy.org/devdocs/release/1.20.0-notes.html#deprecations
"""

The above exception was the direct cause of the following exception:

Traceback (most recent call last):
  File "/home/yfzhang/DanceTrack/TrackEval/trackeval/eval.py", line 81, in evaluate
    results = pool.map(_eval_sequence, seq_list)
              ^^^^^^^^^^^^^^^^^^^^^^^^^^^^^^^^^^
  File "/data1/yfzhang/anaconda3/lib/python3.11/multiprocessing/pool.py", line 367, in map
    return self._map_async(func, iterable, mapstar, chunksize).get()
           ^^^^^^^^^^^^^^^^^^^^^^^^^^^^^^^^^^^^^^^^^^^^^^^^^^^^^^^^^
  File "/data1/yfzhang/anaconda3/lib/python3.11/multiprocessing/pool.py", line 774, in get
    raise self._value
AttributeError: module 'numpy' has no attribute 'float'.
`np.float` was a deprecated alias for the builtin `float`. To avoid this error in existing code, use `float` by itself. Doing this will not modify any behavior and is safe. If you specifically wanted the numpy scalar type, use `np.float64` here.
The aliases was originally deprecated in NumPy 1.20; for more details and guidance see the original release note at:
    https://numpy.org/devdocs/release/1.20.0-notes.html#deprecations





MotChallenge2DBox

multiprocessing.pool.RemoteTraceback: 
"""
Traceback (most recent call last):
  File "/data1/yfzhang/anaconda3/lib/python3.11/multiprocessing/pool.py", line 125, in worker
    result = (True, func(*args, **kwds))
                    ^^^^^^^^^^^^^^^^^^^
  File "/data1/yfzhang/anaconda3/lib/python3.11/multiprocessing/pool.py", line 48, in mapstar
    return list(map(*args))
           ^^^^^^^^^^^^^^^^
  File "/home/yfzhang/DanceTrack/TrackEval/trackeval/_timing.py", line 64, in wrap
    return f(*args, **kw)
           ^^^^^^^^^^^^^^
  File "/home/yfzhang/DanceTrack/TrackEval/trackeval/eval.py", line 191, in eval_sequence
    raw_data = dataset.get_raw_seq_data(tracker, seq)
               ^^^^^^^^^^^^^^^^^^^^^^^^^^^^^^^^^^^^^^
  File "/home/yfzhang/DanceTrack/TrackEval/trackeval/_timing.py", line 64, in wrap
    return f(*args, **kw)
           ^^^^^^^^^^^^^^
  File "/home/yfzhang/DanceTrack/TrackEval/trackeval/datasets/_base_dataset.py", line 92, in get_raw_seq_data
    raw_gt_data = self._load_raw_file(tracker, seq, is_gt=True)
                  ^^^^^^^^^^^^^^^^^^^^^^^^^^^^^^^^^^^^^^^^^^^^^
  File "/home/yfzhang/DanceTrack/TrackEval/trackeval/datasets/mot_challenge_2d_box.py", line 228, in _load_raw_file
    time_data = np.asarray(read_data[time_key], dtype=np.float)
                                                      ^^^^^^^^
  File "/data1/yfzhang/anaconda3/lib/python3.11/site-packages/numpy/__init__.py", line 305, in __getattr__
    raise AttributeError(__former_attrs__[attr])
AttributeError: module 'numpy' has no attribute 'float'.
`np.float` was a deprecated alias for the builtin `float`. To avoid this error in existing code, use `float` by itself. Doing this will not modify any behavior and is safe. If you specifically wanted the numpy scalar type, use `np.float64` here.
The aliases was originally deprecated in NumPy 1.20; for more details and guidance see the original release note at:
    https://numpy.org/devdocs/release/1.20.0-notes.html#deprecations
"""

The above exception was the direct cause of the following exception:

Traceback (most recent call last):
  File "/home/yfzhang/DanceTrack/TrackEval/trackeval/eval.py", line 81, in evaluate
    results = pool.map(_eval_sequence, seq_list)
              ^^^^^^^^^^^^^^^^^^^^^^^^^^^^^^^^^^
  File "/data1/yfzhang/anaconda3/lib/python3.11/multiprocessing/pool.py", line 367, in map
    return self._map_async(func, iterable, mapstar, chunksize).get()
           ^^^^^^^^^^^^^^^^^^^^^^^^^^^^^^^^^^^^^^^^^^^^^^^^^^^^^^^^^
  File "/data1/yfzhang/anaconda3/lib/python3.11/multiprocessing/pool.py", line 774, in get
    raise self._value
AttributeError: module 'numpy' has no attribute 'float'.
`np.float` was a deprecated alias for the builtin `float`. To avoid this error in existing code, use `float` by itself. Doing this will not modify any behavior and is safe. If you specifically wanted the numpy scalar type, use `np.float64` here.
The aliases was originally deprecated in NumPy 1.20; for more details and guidance see the original release note at:
    https://numpy.org/devdocs/release/1.20.0-notes.html#deprecations





